Workbook
Name Slicer_Driver: #N/A
Name Slicer_Race: #N/A
Name Slicer_Season: #N/A
Name Slicer_Team: #N/A
Name Slicer_Weather: #N/A

Sheet F1_2018_2026_RACE_DATA
A1: Season | B1: Round | C1: Race | D1: Driver | E1: Abbreviation | F1: Team | G1: StartPosition | H1: FinishPosition | I1: RacePoints | J1: Podium | K1: Status | L1: TotalLaps | M1: FastestLap | N1: AverageLapTime | O1: FastestS1 | P1: FastestS2 | Q1: FastestS3 | R1: PitStopLaps | S1: Weather | T1: NoPitStops | U1: Grid position
A2: 2018 | B2: 1 | C2: Australian Grand Prix | D2: Sebastian Vettel | E2: VET | F2: Ferrari | G2: 3 | H2: 1 | I2: 25 | J2: Yes | K2: Finished | L2: 58 | M2: 86.469 | N2: 87.894914 | O2: 28.891 | P2: 23.198 | Q2: 34.334 | R2: 26 | S2: Wet | T2: =IF(TRIM(Table1[[#This Row],[PitStopLaps]])="",0, LEN(Table1[[#This Row],[PitStopLaps]])-LEN(SUBSTITUTE(Table1[[#This Row],[PitStopLaps]],",",""))+1) -> 1 | U2: =Table1[[#This Row],[StartPosition]]-Table1[[#This Row],[FinishPosition]] -> 2
A3: 2018 | B3: 1 | C3: Australian Grand Prix | D3: Lewis Hamilton | E3: HAM | F3: Mercedes | G3: 1 | H3: 2 | I3: 18 | J3: Yes | K3: Finished | L3: 58 | M3: 86.444 | N3: 87.817533 | O3: 28.76 | P3: 23.092 | Q3: 34.247 | R3: 19 | S3: Wet | T3: =IF(TRIM(Table1[[#This Row],[PitStopLaps]])="",0, LEN(Table1[[#This Row],[PitStopLaps]])-LEN(SUBSTITUTE(Table1[[#This Row],[PitStopLaps]],",",""))+1) -> 1 | U3: =Table1[[#This Row],[StartPosition]]-Table1[[#This Row],[FinishPosition]] -> -1
A4: 2018 | B4: 1 | C4: Australian Grand Prix | D4: Kimi RÃ¤ikkÃ¶nen | E4: RAI | F4: Ferrari | G4: 2 | H4: 3 | I4: 15 | J4: Yes | K4: Finished | L4: 58 | M4: 86.373 | N4: 87.897511 | O4: 28.698 | P4: 23.101 | Q4: 34.347 | R4: 18 | S4: Wet | T4: =IF(TRIM(Table1[[#This Row],[PitStopLaps]])="",0, LEN(Table1[[#This Row],[PitStopLaps]])-LEN(SUBSTITUTE(Table1[[#This Row],[PitStopLaps]],",",""))+1) -> 1 | U4: =Table1[[#This Row],[StartPosition]]-Table1[[#This Row],[FinishPosition]] -> -1
A5: 2018 | B5: 1 | C5: Australian Grand Prix | D5: Daniel Ricciardo | E5: RIC | F5: Red Bull Racing | G5: 8 | H5: 4 | I5: 12 | J5: No | K5: Finished | L5: 58 | M5: 85.945 | N5: 88.466166 | O5: 28.651 | P5: 23.044 | Q5: 34.089 | R5: 26 | S5: Wet | T5: =IF(TRIM(Table1[[#This Row],[PitStopLaps]])="",0, LEN(Table1[[#This Row],[PitStopLaps]])-LEN(SUBSTITUTE(Table1[[#This Row],[PitStopLaps]],",",""))+1) -> 1 | U5: =Table1[[#This Row],[StartPosition]]-Table1[[#This Row],[FinishPosition]] -> 4
A6: 2018 | B6: 1 | C6: Australian Grand Prix | D6: Fernando Alonso | E6: ALO | F6: McLaren | G6: 10 | H6: 5 | I6: 10 | J6: No | K6: Finished | L6: 58 | M6: 86.978 | N6: 89.019833 | O6: 28.976 | P6: 23.406 | Q6: 34.454 | R6: 26 | S6: Wet | T6: =IF(TRIM(Table1[[#This Row],[PitStopLaps]])="",0, LEN(Table1[[#This Row],[PitStopLaps]])-LEN(SUBSTITUTE(Table1[[#This Row],[PitStopLaps]],",",""))+1) -> 1 | U6: =Table1[[#This Row],[StartPosition]]-Table1[[#This Row],[FinishPosition]] -> 5
A7: 2018 | B7: 1 | C7: Australian Grand Prix | D7: Max Verstappen | E7: VER | F7: Red Bull Racing | G7: 4 | H7: 6 | I7: 8 | J7: No | K7: Finished | L7: 58 | M7: 86.88 | N7: 88.975911 | O7: 28.941 | P7: 23.251 | Q7: 34.464 | R7: 21 | S7: Wet | T7: =IF(TRIM(Table1[[#This Row],[PitStopLaps]])="",0, LEN(Table1[[#This Row],[PitStopLaps]])-LEN(SUBSTITUTE(Table1[[#This Row],[PitStopLaps]],",",""))+1) -> 1 | U7: =Table1[[#This Row],[StartPosition]]-Table1[[#This Row],[FinishPosition]] -> -2
A8: 2018 | B8: 1 | C8: Australian Grand Prix | D8: Nico Hulkenberg | E8: HUL | F8: Renault | G8: 7 | H8: 7 | I8: 6 | J8: No | K8: Finished | L8: 58 | M8: 87.081 | N8: 89.073478 | O8: 28.989 | P8: 23.404 | Q8: 34.549 | R8: 24 | S8: Wet | T8: =IF(TRIM(Table1[[#This Row],[PitStopLaps]])="",0, LEN(Table1[[#This Row],[PitStopLaps]])-LEN(SUBSTITUTE(Table1[[#This Row],[PitStopLaps]],",",""))+1) -> 1 | U8: =Table1[[#This Row],[StartPosition]]-Table1[[#This Row],[FinishPosition]] -> 0
A9: 2018 | B9: 1 | C9: Australian Grand Prix | D9: Valtteri Bottas | E9: BOT | F9: Mercedes | G9: 15 | H9: 8 | I9: 4 | J9: No | K9: Finished | L9: 58 | M9: 87.019 | N9: 89.266914 | O9: 28.893 | P9: 23.278 | Q9: 34.53 | R9: 25 | S9: Wet | T9: =IF(TRIM(Table1[[#This Row],[PitStopLaps]])="",0, LEN(Table1[[#This Row],[PitStopLaps]])-LEN(SUBSTITUTE(Table1[[#This Row],[PitStopLaps]],",",""))+1) -> 1 | U9: =Table1[[#This Row],[StartPosition]]-Table1[[#This Row],[FinishPosition]] -> 7
A10: 2018 | B10: 1 | C10: Australian Grand Prix | D10: Stoffel Vandoorne | E10: VAN | F10: McLaren | G10: 11 | H10: 9 | I10: 2 | J10: No | K10: Finished | L10: 58 | M10: 86.958 | N10: 89.294042 | O10: 28.902 | P10: 23.455 | Q10: 34.493 | R10: 25 | S10: Wet | T10: =IF(TRIM(Table1[[#This Row],[PitStopLaps]])="",0, LEN(Table1[[#This Row],[PitStopLaps]])-LEN(SUBSTITUTE(Table1[[#This Row],[PitStopLaps]],",",""))+1) -> 1 | U10: =Table1[[#This Row],[StartPosition]]-Table1[[#This Row],[FinishPosition]] -> 2
A11: 2018 | B11: 1 | C11: Australian Grand Prix | D11: Carlos Sainz | E11: SAI | F11: Renault | G11: 9 | H11: 10 | I11: 1 | J11: No | K11: Finished | L11: 58 | M11: 87.944 | N11: 89.356511 | O11: 29.315 | P11: 23.61 | Q11: 34.811 | R11: 22 | S11: Wet | T11: =IF(TRIM(Table1[[#This Row],[PitStopLaps]])="",0, LEN(Table1[[#This Row],[PitStopLaps]])-LEN(SUBSTITUTE(Table1[[#This Row],[PitStopLaps]],",",""))+1) -> 1 | U11: =Table1[[#This Row],[StartPosition]]-Table1[[#This Row],[FinishPosition]] -> -1
A12: 2018 | B12: 1 | C12: Australian Grand Prix | D12: Sergio Perez | E12: PER | F12: Force India | G12: 12 | H12: 11 | I12: 0 | J12: No | K12: Finished | L12: 58 | M12: 87.633 | N12: 89.530956 | O12: 29.174 | P12: 23.557 | Q12: 34.877 | R12: 24 | S12: Wet | T12: =IF(TRIM(Table1[[#This Row],[PitStopLaps]])="",0, LEN(Table1[[#This Row],[PitStopLaps]])-LEN(SUBSTITUTE(Table1[[#This Row],[PitStopLaps]],",",""))+1) -> 1 | U12: =Table1[[#This Row],[StartPosition]]-Table1[[#This Row],[FinishPosition]] -> 1
A13: 2018 | B13: 1 | C13: Australian Grand Prix | D13: Esteban Ocon | E13: OCO | F13: Force India | G13: 14 | H13: 12 | I13: 0 | J13: No | K13: Finished | L13: 58 | M13: 87.6 | N13: 89.874066 | O13: 29.097 | P13: 23.494 | Q13: 34.996 | R13: 23 | S13: Wet | T13: =IF(TRIM(Table1[[#This Row],[PitStopLaps]])="",0, LEN(Table1[[#This Row],[PitStopLaps]])-LEN(SUBSTITUTE(Table1[[#This Row],[PitStopLaps]],",",""))+1) -> 1 | U13: =Table1[[#This Row],[StartPosition]]-Table1[[#This Row],[FinishPosition]] -> 2
A14: 2018 | B14: 1 | C14: Australian Grand Prix | D14: Charles Leclerc | E14: LEC | F14: Sauber | G14: 18 | H14: 13 | I14: 0 | J14: No | K14: Finished | L14: 58 | M14: 88.759 | N14: 90.349555 | O14: 29.506 | P14: 23.818 | Q14: 35.256 | R14: 20,27 | S14: Wet | T14: =IF(TRIM(Table1[[#This Row],[PitStopLaps]])="",0, LEN(Table1[[#This Row],[PitStopLaps]])-LEN(SUBSTITUTE(Table1[[#This Row],[PitStopLaps]],",",""))+1) -> 2 | U14: =Table1[[#This Row],[StartPosition]]-Table1[[#This Row],[FinishPosition]] -> 5
A15: 2018 | B15: 1 | C15: Australian Grand Prix | D15: Lance Stroll | E15: STR | F15: Williams | G15: 13 | H15: 14 | I15: 0 | J15: No | K15: Finished | L15: 58 | M15: 88.511 | N15: 90.46034 | O15: 29.369 | P15: 23.572 | Q15: 35.274 | R15: 25,29 | S15: Wet | T15: =IF(TRIM(Table1[[#This Row],[PitStopLaps]])="",0, LEN(Table1[[#This Row],[PitStopLaps]])-LEN(SUBSTITUTE(Table1[[#This Row],[PitStopLaps]],",",""))+1) -> 2 | U15: =Table1[[#This Row],[StartPosition]]-Table1[[#This Row],[FinishPosition]] -> -1
A16: 2018 | B16: 1 | C16: Australian Grand Prix | D16: Brendon Hartley | E16: HAR | F16: Toro Rosso | G16: 16 | H16: 15 | I16: 0 | J16: No | K16: +1 Lap | L16: 57 | M16: 88.176 | N16: 90.385318 | O16: 29.27 | P16: 23.587 | Q16: 35.181 | R16: 1,22 | S16: Wet | T16: =IF(TRIM(Table1[[#This Row],[PitStopLaps]])="",0, LEN(Table1[[#This Row],[PitStopLaps]])-LEN(SUBSTITUTE(Table1[[#This Row],[PitStopLaps]],",",""))+1) -> 2 | U16: =Table1[[#This Row],[StartPosition]]-Table1[[#This Row],[FinishPosition]] -> 1
A17: 2018 | B17: 1 | C17: Australian Grand Prix | D17: Romain Grosjean | E17: GRO | F17: Haas F1 Team | G17: 6 | H17: 16 | I17: 0 | J17: No | K17: Wheel | L17: 24 | M17: 88.805 | N17: 90.128263 | O17: 29.64 | P17: 23.791 | Q17: 35.374 | R17: 24 | S17: Wet | T17: =IF(TRIM(Table1[[#This Row],[PitStopLaps]])="",0, LEN(Table1[[#This Row],[PitStopLaps]])-LEN(SUBSTITUTE(Table1[[#This Row],[PitStopLaps]],",",""))+1) -> 1 | U17: =Table1[[#This Row],[StartPosition]]-Table1[[#This Row],[FinishPosition]] -> -10
A18: 2018 | B18: 1 | C18: Australian Grand Prix | D18: Kevin Magnussen | E18: MAG | F18: Haas F1 Team | G18: 5 | H18: 17 | I18: 0 | J18: No | K18: Wheel | L18: 22 | M18: 89.534 | N18: 90.256352 | O18: 29.873 | P18: 23.822 | Q18: 35.839 | R18: 22 | S18: Wet | T18: =IF(TRIM(Table1[[#This Row],[PitStopLaps]])="",0, LEN(Table1[[#This Row],[PitStopLaps]])-LEN(SUBSTITUTE(Table1[[#This Row],[PitStopLaps]],",",""))+1) -> 1 | U18: =Table1[[#This Row],[StartPosition]]-Table1[[#This Row],[FinishPosition]] -> -12
A19: 2018 | B19: 1 | C19: Australian Grand Prix | D19: Pierre Gasly | E19: GAS | F19: Toro Rosso | G19: 20 | H19: 18 | I19: 0 | J19: No | K19: Engine | L19: 14 | M19: 90.649 | N19: 91.997111 | O19: 30.141 | P19: 24.245 | Q19: 36.209 | R19: 14 | S19: Wet | T19: =IF(TRIM(Table1[[#This Row],[PitStopLaps]])="",0, LEN(Table1[[#This Row],[PitStopLaps]])-LEN(SUBSTITUTE(Table1[[#This Row],[PitStopLaps]],",",""))+1) -> 1 | U19: =Table1[[#This Row],[StartPosition]]-Table1[[#This Row],[FinishPosition]] -> 2
A20: 2018 | B20: 1 | C20: Australian Grand Prix | D20: Marcus Ericsson | E20: ERI | F20: Sauber | G20: 17 | H20: 19 | I20: 0 | J20: No | K20: Steering | L20: 6 | M20: 92.289 | N20: 92.289 | O20: 30.732 | P20: 24.546 | Q20: 37.011 | R20: 6 | S20: Wet | T20: =IF(TRIM(Table1[[#This Row],[PitStopLaps]])="",0, LEN(Table1[[#This Row],[PitStopLaps]])-LEN(SUBSTITUTE(Table1[[#This Row],[PitStopLaps]],",",""))+1) -> 1 | U20: =Table1[[#This Row],[StartPosition]]-Table1[[#This Row],[FinishPosition]] -> -2
A21: 2018 | B21: 1 | C21: Australian Grand Prix | D21: Sergey Sirotkin | E21: SIR | F21: Williams | G21: 19 | H21: 20 | I21: 0 | J21: No | K21: Brakes | L21: 5 | S21: Wet | T21: =IF(TRIM(Table1[[#This Row],[PitStopLaps]])="",0, LEN(Table1[[#This Row],[PitStopLaps]])-LEN(SUBSTITUTE(Table1[[#This Row],[PitStopLaps]],",",""))+1) -> 0 | U21: =Table1[[#This Row],[StartPosition]]-Table1[[#This Row],[FinishPosition]] -> -1
A22: 2018 | B22: 2 | C22: Bahrain Grand Prix | D22: Sebastian Vettel | E22: VET | F22: Ferrari | G22: 1 | H22: 1 | I22: 25 | J22: Yes | K22: Finished | L22: 57 | M22: 94.453 | N22: 95.37542 | O22: 29.933 | P22: 40.926 | Q22: 23.357 | R22: 17 | S22: Dry | T22: =IF(TRIM(Table1[[#This Row],[PitStopLaps]])="",0, LEN(Table1[[#This Row],[PitStopLaps]])-LEN(SUBSTITUTE(Table1[[#This Row],[PitStopLaps]],",",""))+1) -> 1 | U22: =Table1[[#This Row],[StartPosition]]-Table1[[#This Row],[FinishPosition]] -> 0
A23: 2018 | B23: 2 | C23: Bahrain Grand Prix | D23: Valtteri Bottas | E23: BOT | F23: Mercedes | G23: 3 | H23: 2 | I23: 18 | J23: Yes | K23: Finished | L23: 57 | M23: 93.74 | N23: 95.32562 | O23: 29.826 | P23: 40.676 | Q23: 23.14 | R23: 19 | S23: Dry | T23: =IF(TRIM(Table1[[#This Row],[PitStopLaps]])="",0, LEN(Table1[[#This Row],[PitStopLaps]])-LEN(SUBSTITUTE(Table1[[#This Row],[PitStopLaps]],",",""))+1) -> 1 | U23: =Table1[[#This Row],[StartPosition]]-Table1[[#This Row],[FinishPosition]] -> 1
A24: 2018 | B24: 2 | C24: Bahrain Grand Prix | D24: Lewis Hamilton | E24: HAM | F24: Mercedes | G24: 9 | H24: 3 | I24: 15 | J24: Yes | K24: Finished | L24: 57 | M24: 93.953 | N24: 95.25668 | O24: 29.751 | P24: 40.772 | Q24: 23.12 | R24: 25 | S24: Dry | T24: =IF(TRIM(Table1[[#This Row],[PitStopLaps]])="",0, LEN(Table1[[#This Row],[PitStopLaps]])-LEN(SUBSTITUTE(Table1[[#This Row],[PitStopLaps]],",",""))+1) -> 1 | U24: =Table1[[#This Row],[StartPosition]]-Table1[[#This Row],[FinishPosition]] -> 6
A25: 2018 | B25: 2 | C25: Bahrain Grand Prix | D25: Pierre Gasly | E25: GAS | F25: Toro Rosso | G25: 5 | H25: 4 | I25: 12 | J25: No | K25: Finished | L25: 57 | M25: 94.863 | N25: 95.908333 | O25: 30.319 | P25: 40.912 | Q25: 23.34 | R25: 15,34 | S25: Dry | T25: =IF(TRIM(Table1[[#This Row],[PitStopLaps]])="",0, LEN(Table1[[#This Row],[PitStopLaps]])-LEN(SUBSTITUTE(Table1[[#This Row],[PitStopLaps]],",",""))+1) -> 2 | U25: =Table1[[#This Row],[StartPosition]]-Table1[[#This Row],[FinishPosition]] -> 1
A26: 2018 | B26: 2 | C26: Bahrain Grand Prix | D26: Kevin Magnussen | E26: MAG | F26: Haas F1 Team | G26: 6 | H26: 5 | I26: 10 | J26: No | K26: Finished | L26: 57 | M26: 94.327 | N26: 96.149666 | O26: 30.015 | P26: 40.797 | Q26: 23.41 | R26: 13,27 | S26: Dry | T26: =IF(TRIM(Table1[[#This Row],[PitStopLaps]])="",0, LEN(Table1[[#This Row],[PitStopLaps]])-LEN(SUBSTITUTE(Table1[[#This Row],[PitStopLaps]],",",""))+1) -> 2 | U26: =Table1[[#This Row],[StartPosition]]-Table1[[#This Row],[FinishPosition]] -> 1
A27: 2018 | B27: 2 | C27: Bahrain Grand Prix | D27: Nico Hulkenberg | E27: HUL | F27: Renault | G27: 7 | H27: 6 | I27: 8 | J27: No | K27: Finished | L27: 57 | M27: 94.667 | N27: 96.615659 | O27: 29.923 | P27: 40.908 | Q27: 23.276 | R27: 15,39 | S27: Dry | T27: =IF(TRIM(Table1[[#This Row],[PitStopLaps]])="",0, LEN(Table1[[#This Row],[PitStopLaps]])-LEN(SUBSTITUTE(Table1[[#This Row],[PitStopLaps]],",",""))+1) -> 2 | U27: =Table1[[#This Row],[StartPosition]]-Table1[[#This Row],[FinishPosition]] -> 1
A28: 2018 | B28: 2 | C28: Bahrain Grand Prix | D28: Fernando Alonso | E28: ALO | F28: McLaren | G28: 13 | H28: 7 | I28: 6 | J28: No | K28: +1 Lap | L28: 56 | M28: 94.168 | N28: 96.58013 | O28: 30.163 | P28: 40.566 | Q28: 23.343 | R28: 14,39 | S28: Dry | T28: =IF(TRIM(Table1[[#This Row],[PitStopLaps]])="",0, LEN(Table1[[#This Row],[PitStopLaps]])-LEN(SUBSTITUTE(Table1[[#This Row],[PitStopLaps]],",",""))+1) -> 2 | U28: =Table1[[#This Row],[StartPosition]]-Table1[[#This Row],[FinishPosition]] -> 6
A29: 2018 | B29: 2 | C29: Bahrain Grand Prix | D29: Stoffel Vandoorne | E29: VAN | F29: McLaren | G29: 14 | H29: 8 | I29: 4 | J29: No | K29: +1 Lap | L29: 56 | M29: 95.131 | N29: 96.682744 | O29: 30.236 | P29: 41.021 | Q29: 23.453 | R29: 10,28 | S29: Dry | T29: =IF(TRIM(Table1[[#This Row],[PitStopLaps]])="",0, LEN(Table1[[#This Row],[PitStopLaps]])-LEN(SUBSTITUTE(Table1[[#This Row],[PitStopLaps]],",",""))+1) -> 2 | U29: =Table1[[#This Row],[StartPosition]]-Table1[[#This Row],[FinishPosition]] -> 6
A30: 2018 | B30: 2 | C30: Bahrain Grand Prix | D30: Marcus Ericsson | E30: ERI | F30: Sauber | G30: 17 | H30: 9 | I30: 2 | J30: No | K30: +1 Lap | L30: 56 | M30: 95.093 | N30: 97.149958 | O30: 30.138 | P30: 41.223 | Q30: 23.66 | R30: 23 | S30: Dry | T30: =IF(TRIM(Table1[[#This Row],[PitStopLaps]])="",0, LEN(Table1[[#This Row],[PitStopLaps]])-LEN(SUBSTITUTE(Table1[[#This Row],[PitStopLaps]],",",""))+1) -> 1 | U30: =Table1[[#This Row],[StartPosition]]-Table1[[#This Row],[FinishPosition]] -> 8
A31: 2018 | B31: 2 | C31: Bahrain Grand Prix | D31: Esteban Ocon | E31: OCO | F31: Force India | G31: 8 | H31: 10 | I31: 1 | J31: No | K31: +1 Lap | L31: 56 | M31: 95.043 | N31: 96.944717 | O31: 30.201 | P31: 41.156 | Q31: 23.488 | R31: 15,35 | S31: Dry | T31: =IF(TRIM(Table1[[#This Row],[PitStopLaps]])="",0, LEN(Table1[[#This Row],[PitStopLaps]])-LEN(SUBSTITUTE(Table1[[#This Row],[PitStopLaps]],",",""))+1) -> 2 | U31: =Table1[[#This Row],[StartPosition]]-Table1[[#This Row],[FinishPosition]] -> -2
A32: 2018 | B32: 2 | C32: Bahrain Grand Prix | D32: Carlos Sainz | E32: SAI | F32: Renault | G32: 10 | H32: 11 | I32: 0 | J32: No | K32: +1 Lap | L32: 56 | M32: 95.535 | N32: 96.987369 | O32: 30.252 | P32: 41.502 | Q32: 23.619 | R32: 16,26 | S32: Dry | T32: =IF(TRIM(Table1[[#This Row],[PitStopLaps]])="",0, LEN(Table1[[#This Row],[PitStopLaps]])-LEN(SUBSTITUTE(Table1[[#This Row],[PitStopLaps]],",",""))+1) -> 2 | U32: =Table1[[#This Row],[StartPosition]]-Table1[[#This Row],[FinishPosition]] -> -1
A33: 2018 | B33: 2 | C33: Bahrain Grand Prix | D33: Charles Leclerc | E33: LEC | F33: Sauber | G33: 19 | H33: 12 | I33: 0 | J33: No | K33: +1 Lap | L33: 56 | M33: 95.058 | N33: 97.187729 | O33: 30.325 | P33: 41.101 | Q33: 23.463 | R33: 3,34 | S33: Dry | T33: =IF(TRIM(Table1[[#This Row],[PitStopLaps]])="",0, LEN(Table1[[#This Row],[PitStopLaps]])-LEN(SUBSTITUTE(Table1[[#This Row],[PitStopLaps]],",",""))+1) -> 2 | U33: =Table1[[#This Row],[StartPosition]]-Table1[[#This Row],[FinishPosition]] -> 7
A34: 2018 | B34: 2 | C34: Bahrain Grand Prix | D34: Romain Grosjean | E34: GRO | F34: Haas F1 Team | G34: 16 | H34: 13 | I34: 0 | J34: No | K34: +1 Lap | L34: 56 | M34: 94.053 | N34: 96.58484 | O34: 29.93 | P34: 40.696 | Q34: 23.397 | R34: 18,30,45 | S34: Dry | T34: =IF(TRIM(Table1[[#This Row],[PitStopLaps]])="",0, LEN(Table1[[#This Row],[PitStopLaps]])-LEN(SUBSTITUTE(Table1[[#This Row],[PitStopLaps]],",",""))+1) -> 3 | U34: =Table1[[#This Row],[StartPosition]]-Table1[[#This Row],[FinishPosition]] -> 3
A35: 2018 | B35: 2 | C35: Bahrain Grand Prix | D35: Lance Stroll | E35: STR | F35: Williams | G35: 20 | H35: 14 | I35: 0 | J35: No | K35: +1 Lap | L35: 56 | M35: 95.266 | N35: 97.384978 | O35: 30.387 | P35: 41.088 | Q35: 23.677 | R35: 10,29 | S35: Dry | T35: =IF(TRIM(Table1[[#This Row],[PitStopLaps]])="",0, LEN(Table1[[#This Row],[PitStopLaps]])-LEN(SUBSTITUTE(Table1[[#This Row],[PitStopLaps]],",",""))+1) -> 2 | U35: =Table1[[#This Row],[StartPosition]]-Table1[[#This Row],[FinishPosition]] -> 6
A36: 2018 | B36: 2 | C36: Bahrain Grand Prix | D36: Sergey Sirotkin | E36: SIR | F36: Williams | G36: 18 | H36: 15 | I36: 0 | J36: No | K36: +1 Lap | L36: 56 | M36: 94.563 | N36: 97.487695 | O36: 30.263 | P36: 40.929 | Q36: 23.364 | R36: 22,40 | S36: Dry | T36: =IF(TRIM(Table1[[#This Row],[PitStopLaps]])="",0, LEN(Table1[[#This Row],[PitStopLaps]])-LEN(SUBSTITUTE(Table1[[#This Row],[PitStopLaps]],",",""))+1) -> 2 | U36: =Table1[[#This Row],[StartPosition]]-Table1[[#This Row],[FinishPosition]] -> 3
A37: 2018 | B37: 2 | C37: Bahrain Grand Prix | D37: Sergio Perez | E37: PER | F37: Force India | G37: 12 | H37: 16 | I37: 0 | J37: No | K37: +1 Lap | L37: 56 | M37: 95.075 | N37: 97.025319 | O37: 30.214 | P37: 41.342 | Q37: 23.411 | R37: 9,32 | S37: Dry | T37: =IF(TRIM(Table1[[#This Row],[PitStopLaps]])="",0, LEN(Table1[[#This Row],[PitStopLaps]])-LEN(SUBSTITUTE(Table1[[#This Row],[PitStopLaps]],",",""))+1) -> 2 | U37: =Table1[[#This Row],[StartPosition]]-Table1[[#This Row],[FinishPosition]] -> -4
A38: 2018 | B38: 2 | C38: Bahrain Grand Prix | D38: Brendon Hartley | E38: HAR | F38: Toro Rosso | G38: 11 | H38: 17 | I38: 0 | J38: No | K38: +1 Lap | L38: 56 | M38: 94.689 | N38: 96.752673 | O38: 30.195 | P38: 41.084 | Q38: 23.277 | R38: 20,42 | S38: Dry | T38: =IF(TRIM(Table1[[#This Row],[PitStopLaps]])="",0, LEN(Table1[[#This Row],[PitStopLaps]])-LEN(SUBSTITUTE(Table1[[#This Row],[PitStopLaps]],",",""))+1) -> 2 | U38: =Table1[[#This Row],[StartPosition]]-Table1[[#This Row],[FinishPosition]] -> -6
A39: 2018 | B39: 2 | C39: Bahrain Grand Prix | D39: Kimi RÃ¤ikkÃ¶nen | E39: RAI | F39: Ferrari | G39: 2 | H39: 18 | I39: 0 | J39: No | K39: Wheel | L39: 34 | M39: 94.337 | N39: 95.499185 | O39: 30.078 | P39: 40.851 | Q39: 23.317 | R39: 18,34 | S39: Dry | T39: =IF(TRIM(Table1[[#This Row],[PitStopLaps]])="",0, LEN(Table1[[#This Row],[PitStopLaps]])-LEN(SUBSTITUTE(Table1[[#This Row],[PitStopLaps]],",",""))+1) -> 2 | U39: =Table1[[#This Row],[StartPosition]]-Table1[[#This Row],[FinishPosition]] -> -16
A40: 2018 | B40: 2 | C40: Bahrain Grand Prix | D40: Max Verstappen | E40: VER | F40: Red Bull Racing | G40: 15 | H40: 19 | I40: 0 | J40: No | K40: Puncture | L40: 4 | R40: 2 | S40: Dry | T40: =IF(TRIM(Table1[[#This Row],[PitStopLaps]])="",0, LEN(Table1[[#This Row],[PitStopLaps]])-LEN(SUBSTITUTE(Table1[[#This Row],[PitStopLaps]],",",""))+1) -> 1 | U40: =Table1[[#This Row],[StartPosition]]-Table1[[#This Row],[FinishPosition]] -> -4
...

Sheet Dashboard
A1: F1 RACE ANALYSIS (2018 - 2020)
A4: Season | Race | Driver | Team | Weather
A5: TOTAL RACES | V5: Fastest Lap Time
A7: ='Weather vs Race Performance'!D199 -> 186 | V7: =MIN(F1_2018_2026_RACE_DATA!M2:M3747) -> 55.404
A9: TOTAL DRIVERS | V9: Driver with Fastest Lap
A11: =COUNTA(_xlfn.UNIQUE('Weather vs Race Performance'!A10:A54)) -> 45 | V11: =_xlfn.XLOOKUP(MIN(F1_2018_2026_RACE_DATA!M2:M3747),F1_2018_2026_RACE_DATA!M2:M3747,F1_2018_2026_RACE_DATA!D2:D3747) -> George Russell
A13: Total Teams | V13: Grand Prix with Fastest Lap
A15: =COUNTA('Weather vs Race Performance'!G2:G22) -> 21 | V15: =_xlfn.XLOOKUP(MIN(F1_2018_2026_RACE_DATA!M2:M3747),F1_2018_2026_RACE_DATA!M2:M3747,F1_2018_2026_RACE_DATA!C2:C3747) -> Sakhir Grand Prix
A17: TOTAL RACE POINTS | V17: Slowest Average Lap Time
A19: =GETPIVOTDATA("RacePoints",'Weather vs Race Performance'!$J$1) -> 18848.5 | V19: =MAX(F1_2018_2026_RACE_DATA!N2:N3747) -> 127.0968
A21: TOTAL PODIUMS | V21: Driver with Slowest Average Lap
A23: =COUNTIF(F1_2018_2026_RACE_DATA!J2:J3747,"=Yes") -> 558 | V23: =_xlfn.XLOOKUP(MAX(F1_2018_2026_RACE_DATA!N2:N3747),F1_2018_2026_RACE_DATA!N2:N3747,F1_2018_2026_RACE_DATA!D2:D3747) -> Nicholas Latifi
A25: MOST RACE POINT DRIVER | V25: Grand Prix with Slowest Average Lap
A27: ='Weather vs Race Performance'!M3 -> 0 | V27: =_xlfn.XLOOKUP(MAX(F1_2018_2026_RACE_DATA!N2:N3747),F1_2018_2026_RACE_DATA!N2:N3747,F1_2018_2026_RACE_DATA!C2:C3747) -> Singapore Grand Prix
V29: TOTAL RACES
V31: ='Weather vs Race Performance'!D199 -> 186
V33: TOTAL DRIVERS
V35: =COUNTA(_xlfn.UNIQUE('Weather vs Race Performance'!M3:M47)) -> 12
V37: Total Teams
V39: =COUNTA('Weather vs Race Performance'!G2:G22) -> 21
V41: TOTAL RACE POINTS
V43: =GETPIVOTDATA("RacePoints",'Weather vs Race Performance'!$J$1) -> 18848.5
V45: TOTAL PODIUMS
V47: =COUNTIF(F1_2018_2026_RACE_DATA!J2:J3747,"=Yes") -> 558
V49: MOST RACE POINT DRIVER
V51: ='Weather vs Race Performance'!M3 -> 0

Sheet Weather vs Race Performance
A1: Team | B1: (All) | D1: Row Labels | E1: Count of Race | G1: Row Labels | H1: Count of Team | J1: Sum of RacePoints
A2: Season | B2: (All) | D2: 2018 | E2: 400 | G2: Alfa Romeo | H2: 88 | J2: 18848.5 | M2: #VALUE!
D3: 1 | E3: 20 | G3: Alfa Romeo Racing | H3: 120
A4: Row Labels | B4: Average of FinishPosition | D4: 2 | E4: 20 | G4: AlphaTauri | H4: 166 | J4: Average of FinishPosition
A5: Dry | B5: 10.576259 | D5: 3 | E5: 20 | G5: Alpine | H5: 256 | J5: 10.569597
A6: Wet | B6: 10.548673 | D6: 4 | E6: 20 | G6: Aston Martin | H6: 255
A7: Grand Total | B7: 10.569597 | D7: 5 | E7: 20 | G7: Audi | H7: 28 | J7: Sum of AverageLapTime | K7: Column Labels
D8: 6 | E8: 20 | G8: Cadillac | H8: 28 | J8: Row Labels | K8: Dry | L8: Wet | M8: Grand Total
A9: Row Labels | B9: Count of Driver | D9: 7 | E9: 20 | G9: Ferrari | H9: 372 | J9: 2018 | K9: 20521.811 | L9: 13971.024 | M9: 34492.835
A10: Alexander Albon | B10: 143 | D10: 8 | E10: 20 | G10: Force India | H10: 24 | J10: 2019 | K10: 33017.726 | L10: 5182.3855 | M10: 38200.111
A11: Andrea Kimi Antonelli | B11: 1 | D11: 9 | E11: 20 | G11: Haas F1 Team | H11: 372 | J11: 2020 | K11: 21464.969 | L11: 6894.3342 | M11: 28359.304
A12: Antonio Giovinazzi | B12: 60 | D12: 10 | E12: 20 | G12: Kick Sauber | H12: 96 | J12: 2021 | K12: 27596.045 | L12: 7969.8813 | M12: 35565.926
A13: Arvid Lindblad | B13: 14 | D13: 11 | E13: 20 | G13: McLaren | H13: 372 | J13: 2022 | K13: 28094.377 | L13: 11313.278 | M13: 39407.655
A14: Brendon Hartley | B14: 20 | D14: 12 | E14: 20 | G14: Mercedes | H14: 372 | J14: 2023 | K14: 30398.501 | L14: 8137.3924 | M14: 38535.894
A15: Carlos Sainz | B15: 185 | D15: 13 | E15: 20 | G15: Racing Bulls | H15: 76 | J15: 2024 | K15: 33738.92 | L15: 8119.7046 | M15: 41858.625
A16: Charles Leclerc | B16: 186 | D16: 15 | E16: 20 | G16: Racing Point | H16: 92 | J16: 2025 | K16: 30450.406 | L16: 10751.246 | M16: 41201.653
A17: Daniel Ricciardo | B17: 127 | D17: 16 | E17: 20 | G17: RB | H17: 48 | J17: 2026 | K17: 22680.458 | L17: 3651.8949 | M17: 26332.353
A18: Daniil Kvyat | B18: 38 | D18: 17 | E18: 20 | G18: Red Bull Racing | H18: 372 | J18: Grand Total | K18: 247963.21 | L18: 75991.142 | M18: 323954.36
A19: Esteban Ocon | B19: 164 | D19: 18 | E19: 20 | G19: Renault | H19: 116
A20: Fernando Alonso | B20: 148 | D20: 19 | E20: 20 | G20: Sauber | H20: 40
A21: Franco Colapinto | B21: 41 | D21: 20 | E21: 20 | G21: Toro Rosso | H21: 82
A22: Gabriel Bortoleto | B22: 38 | D22: 21 | E22: 20 | G22: Williams | H22: 371
A23: George Russell | B23: 166 | D23: 2019 | E23: 420 | G23: Grand Total | H23: 3746
A24: Guanyu Zhou | B24: 68 | D24: 1 | E24: 20
A25: Isack Hadjar | B25: 35 | D25: 2 | E25: 20
A26: Jack Aitken | B26: 1 | D26: 3 | E26: 20
A27: Jack Doohan | B27: 7 | D27: 4 | E27: 20
A28: Kevin Magnussen | B28: 124 | D28: 5 | E28: 20
A29: Kimi Antonelli | B29: 37 | D29: 6 | E29: 20
A30: Kimi RÃ¤ikkÃ¶nen | B30: 78 | D30: 7 | E30: 20
A31: Lance Stroll | B31: 184 | D31: 8 | E31: 20
A32: Lando Norris | B32: 166 | D32: 9 | E32: 20
A33: Lewis Hamilton | B33: 185 | D33: 10 | E33: 20
A34: Liam Lawson | B34: 49 | D34: 11 | E34: 20
A35: Logan Sargeant | B35: 36 | D35: 12 | E35: 20
... A55: Grand Total | B55: 3746 | D55: 10 | E55: 20
D56: 11 | E56: 20
D57: 12 | E57: 20
D58: 13 | E58: 20
D59: 14 | E59: 20
...

Sheet Finish Vs Starting
A1: Season | B1: (All)
A2: Team | B2: (All)
A4: Row Labels | B4: Average of FinishPosition
A5: 0 | B5: 14.139535 | E5: Starting Position | F5: Finish Position
A6: 1 | B6: 3.5537634 | E6: 0 | F6: 14.139535
A7: 2 | B7: 4.0645161 | E7: 1 | F7: 3.5537634
A8: 3 | B8: 5.4677419 | E8: 2 | F8: 4.0645161
A9: 4 | B9: 5.9032258 | E9: 3 | F9: 5.4677419
A10: 5 | B10: 7.2634409 | E10: 4 | F10: 5.9032258
A11: 6 | B11: 7.7311828 | E11: 5 | F11: 7.2634409
A12: 7 | B12: 8.7297297 | E12: 6 | F12: 7.7311828
A13: 8 | B13: 9.9405405 | E13: 7 | F13: 8.7297297
A14: 9 | B14: 10.322581 | E14: 8 | F14: 9.9405405
A15: 10 | B15: 11.210811 | E15: 9 | F15: 10.322581
A16: 11 | B16: 11.47027 | E16: 10 | F16: 11.210811
A17: 12 | B17: 12.053763 | E17: 11 | F17: 11.47027
... A27: 22 | B27: 18.357143 | E27: 21 | F27: 16.571429
A28: (blank) | E28: 22 | F28: 18.357143
A29: Grand Total | B29: 10.569597

Sheet Fastest Sector Performance
A1: Season | B1: (All)
A3: Row Labels | B3: Average of FastestS1 | C3: Average of FastestS2 | D3: Average of FastestS3
A4: Pietro Fittipaldi | B4: 18.899 | C4: 31.88 | D4: 28.8735
A5: Jack Aitken | B5: 20.011 | C5: 20.415 | D5: 16.889
A6: Sergey Sirotkin | B6: 25.585389 | C6: 35.933556 | D6: 28.357833
A7: Kimi RÃ¤ikkÃ¶nen | B7: 26.285566 | C7: 34.301816 | D7: 27.192711
A8: Daniil Kvyat | B8: 26.328263 | C8: 34.086632 | D8: 27.204974
A9: Franco Colapinto | B9: 26.337359 | C9: 34.087205 | D9: 26.660641
A10: Stoffel Vandoorne | B10: 26.33875 | C10: 35.52825 | D10: 28.3619
A11: Sebastian Vettel | B11: 26.44049 | C11: 34.064878 | D11: 27.242204
A12: Lewis Hamilton | B12: 26.474453 | C12: 33.504503 | D12: 26.61547
A13: Marcus Ericsson | B13: 26.4766 | C13: 35.70395 | D13: 28.6779
A14: Antonio Giovinazzi | B14: 26.509328 | C14: 34.133259 | D14: 26.935207
A15: Carlos Sainz | B15: 26.535595 | C15: 33.975058 | D15: 26.778769
... A49: Grand Total | B49: 26.811686 | C49: 33.991987 | D49: 26.981109

Sheet Average Lap Time by Driver
A1: Race | B1: (All)
A2: Team | B2: (All)
A4: Row Labels | B4: Average of AverageLapTime
A5: Jack Aitken | B5: 58.98091
A6: Pietro Fittipaldi | B6: 82.415328
A7: Oscar Piastri | B7: 88.577324
A8: Nyck De Vries | B8: 88.928918
A9: Kimi Antonelli | B9: 89.136843
A10: Lewis Hamilton | B10: 89.174327
A11: Gabriel Bortoleto | B11: 89.244756
A12: Max Verstappen | B12: 89.271893
A13: Isack Hadjar | B13: 89.325622
A14: Franco Colapinto | B14: 89.366834
A15: Lando Norris | B15: 89.416974
A16: Liam Lawson | B16: 89.595643
... A50: Grand Total | B50: 90.288282

Sheet Driver Championship Points
A1: Season | B1: (All)
A2: Team | B2: (All)
A4: Row Labels | B4: Sum of RacePoints
A5: Max Verstappen | B5: 3003.5 | E5: Sum of RacePoints | F5: Column Labels
A6: Lewis Hamilton | B6: 2491.5 | E6: Row Labels | F6: Alfa Romeo | G6: Alfa Romeo Racing | H6: AlphaTauri | I6: Alpine | J6: Aston Martin | K6: Audi | L6: Cadillac | M6: Ferrari | N6: Force India | O6: Haas F1 Team | P6: Kick Sauber | Q6: McLaren | R6: Mercedes | S6: Racing Bulls | T6: Racing Point | U6: RB | V6: Red Bull Racing | W6: Renault | X6: Sauber | Y6: Toro Rosso | Z6: Williams | AA6: Grand Total
A7: Charles Leclerc | B7: 1727 | E7: Max Verstappen | V7: 3003.5 | AA7: 3003.5
A8: Lando Norris | B8: 1498 | E8: Lewis Hamilton | M8: 306 | R8: 2185.5 | AA8: 2491.5
A9: Carlos Sainz | B9: 1141.5 | E9: Charles Leclerc | M9: 1688 | X9: 39 | AA9: 1727
A10: George Russell | B10: 1130 | E10: Lando Norris | Q10: 1498 | AA10: 1498
A11: Sergio Perez | B11: 1112 | E11: Carlos Sainz | M11: 831.5 | Q11: 201 | W11: 49 | Z11: 60 | AA11: 1141.5
A12: Valtteri Bottas | B12: 1057 | E12: George Russell | R12: 1114 | Z12: 16 | AA12: 1130
A13: Oscar Piastri | B13: 827 | E13: Sergio Perez | L13: 0 | N13: 30 | T13: 203 | V13: 879 | AA13: 1112
A14: Sebastian Vettel | B14: 661 | E14: Valtteri Bottas | F14: 57 | L14: 0 | P14: 0 | R14: 1000 | AA14: 1057
A15: Fernando Alonso | B15: 534 | E15: Oscar Piastri | Q15: 827 | AA15: 827
A16: Daniel Ricciardo | B16: 504 | E16: Sebastian Vettel | J16: 80 | M16: 581 | AA16: 661
A17: Pierre Gasly | B17: 485 | E17: Fernando Alonso | I17: 162 | J17: 322 | Q17: 50 | AA17: 534
A18: Kimi Antonelli | B18: 389 | E18: Daniel Ricciardo | H18: 6 | Q18: 148 | U18: 7 | V18: 170 | W18: 173 | AA18: 504
A19: Esteban Ocon | B19: 382 | E19: Pierre Gasly | H19: 208 | I19: 153 | V19: 63 | Y19: 61 | AA19: 485
A20: Alexander Albon | B20: 313 | E20: Kimi Antonelli | R20: 389 | AA20: 389
A21: Kimi RÃ¤ikkÃ¶nen | B21: 290 | E21: Esteban Ocon | I21: 242 | N21: 29 | O21: 37 | T21: 12 | W21: 62 | AA21: 382
A22: Lance Stroll | B22: 273 | E22: Alexander Albon | V22: 181 | Y22: 16 | Z22: 116 | AA22: 313
A23: Nico Hulkenberg | B23: 216 | E23: Kimi RÃ¤ikkÃ¶nen | G23: 57 | M23: 233 | AA23: 290
A24: Isack Hadjar | B24: 121 | E24: Lance Stroll | J24: 173 | T24: 96 | Z24: 4 | AA24: 273
A25: Kevin Magnussen | B25: 115 | E25: Nico Hulkenberg | J25: 0 | K25: 7 | O25: 42 | P25: 51 | T25: 10 | W25: 106 | AA25: 216
A26: Yuki Tsunoda | B26: 109 | E26: Isack Hadjar | S26: 50 | V26: 71 | AA26: 121
A27: Liam Lawson | B27: 100 | E27: Kevin Magnussen | O27: 115 | AA27: 115
A28: Daniil Kvyat | B28: 69 | E28: Yuki Tsunoda | H28: 58 | S28: 1 | U28: 29 | V28: 21 | AA28: 109
A29: Oliver Bearman | B29: 63 | E29: Liam Lawson | H29: 2 | S29: 80 | U29: 4 | V29: 14 | AA29: 100
A30: Romain Grosjean | B30: 47 | E30: Daniil Kvyat | H30: 32 | Y30: 37 | AA30: 69
A31: Franco Colapinto | B31: 32 | E31: Oliver Bearman | M31: 6 | O31: 57 | AA31: 63
A32: Arvid Lindblad | B32: 30 | E32: Romain Grosjean | O32: 47 | AA32: 47
A33: Gabriel Bortoleto | B33: 29 | E33: Franco Colapinto | I33: 27 | Z33: 5 | AA33: 32
A34: Antonio Giovinazzi | B34: 21 | E34: Arvid Lindblad | S34: 30 | AA34: 30
A35: Guanyu Zhou | B35: 16 | E35: Gabriel Bortoleto | K35: 10 | P35: 19 | AA35: 29
A36: Andrea Kimi Antonelli | B36: 12 | E36: Antonio Giovinazzi | G36: 21 | AA36: 21
A37: Mick Schumacher | B37: 12 | E37: Guanyu Zhou | F37: 12 | P37: 4 | AA37: 16
A38: Stoffel Vandoorne | B38: 12 | E38: Andrea Kimi Antonelli | R38: 12 | AA38: 12
A39: Nicholas Latifi | B39: 9 | E39: Mick Schumacher | O39: 12 | AA39: 12
A40: Marcus Ericsson | B40: 9 | E40: Stoffel Vandoorne | Q40: 12 | AA40: 12
A41: Brendon Hartley | B41: 4 | E41: Nicholas Latifi | Z41: 9 | AA41: 9
...

Sheet Constructor Points Comparison
A3: Sum of RacePoints | B3: Column Labels
A4: Row Labels | B4: 2018 | C4: 2019 | D4: 2020 | E4: 2021 | F4: 2022 | G4: 2023 | H4: 2024 | I4: 2025 | J4: 2026 | K4: Grand Total | M4: Row Labels | N4: Sum of RacePoints
A5: Cadillac | J5: 0 | K5: 0 | M5: Alexander Albon | N5: 313
A6: Audi | J6: 17 | K6: 17 | M6: Andrea Kimi Antonelli | N6: 12
A7: RB | H7: 40 | K7: 40 | M7: Antonio Giovinazzi | N7: 21
A8: Sauber | B8: 48 | K8: 48 | M8: Arvid Lindblad | N8: 30
A9: Force India | B9: 59 | K9: 59 | M9: Brendon Hartley | N9: 4
A10: Alfa Romeo | F10: 53 | G10: 16 | K10: 69 | M10: Carlos Sainz | N10: 1141.5
A11: Kick Sauber | H11: 4 | I11: 70 | K11: 74 | M11: Charles Leclerc | N11: 1727
A12: Alfa Romeo Racing | C12: 57 | D12: 8 | E12: 13 | K12: 78 | M12: Daniel Ricciardo | N12: 504
A13: Toro Rosso | B13: 33 | C13: 85 | K13: 118 | M13: Daniil Kvyat | N13: 69
A14: Racing Bulls | I14: 88 | J14: 73 | K14: 161 | M14: Esteban Ocon | N14: 382
A15: Williams | B15: 4 | C15: 1 | D15: 0 | E15: 23 | F15: 8 | G15: 26 | H15: 17 | I15: 124 | J15: 11 | K15: 214 | M15: Fernando Alonso | N15: 534
A16: AlphaTauri | D16: 107 | E16: 142 | F16: 35 | G16: 22 | K16: 306 | M16: Franco Colapinto | N16: 32
A17: Haas F1 Team | B17: 93 | C17: 28 | D17: 3 | E17: 0 | F17: 33 | G17: 9 | H17: 51 | I17: 73 | J17: 20 | K17: 310 | M17: Gabriel Bortoleto | N17: 29
A18: Racing Point | B18: 38 | C18: 73 | D18: 210 | K18: 321 | M18: George Russell | N18: 1130
A19: Renault | B19: 118 | C19: 91 | D19: 181 | K19: 390 | M19: Guanyu Zhou | N19: 16
A20: Aston Martin | E20: 77 | F20: 55 | G20: 266 | H20: 94 | I20: 80 | J20: 3 | K20: 575 | M20: Isack Hadjar | N20: 121
A21: Alpine | E21: 155 | F21: 170 | G21: 110 | H21: 63 | I21: 20 | J21: 66 | K21: 584 | M21: Jack Aitken | N21: 0
A22: McLaren | B22: 62 | C22: 145 | D22: 202 | E22: 274 | F22: 150 | G22: 266 | H22: 609 | I22: 775 | J22: 253 | K22: 2736 | M22: Jack Doohan | N22: 0
A23: Ferrari | B23: 541 | C23: 504 | D23: 131 | E23: 322.5 | F23: 519 | G23: 363 | H23: 595 | I23: 360 | J23: 310 | K23: 3645.5 | M23: Kevin Magnussen | N23: 115
A24: Red Bull Racing | B24: 409 | C24: 417 | D24: 319 | E24: 578.5 | F24: 724 | G24: 790 | H24: 537 | I24: 410 | J24: 218 | K24: 4402.5 | M24: Kimi Antonelli | N24: 389
A25: Mercedes | B25: 615 | C25: 739 | D25: 573 | E25: 604.5 | F25: 495 | G25: 374 | H25: 433 | I25: 424 | J25: 443 | K25: 4700.5 | M25: Kimi RÃ¤ikkÃ¶nen | N25: 290
A26: Grand Total | B26: 2020 | C26: 2140 | D26: 1734 | E26: 2189.5 | F26: 2242 | G26: 2242 | H26: 2443 | I26: 2424 | J26: 1414 | K26: 18848.5 | M26: Lance Stroll | N26: 273
M27: Lando Norris | N27: 1498
M28: Lewis Hamilton | N28: 2491.5
M29: Liam Lawson | N29: 100
M30: Logan Sargeant | N30: 1
M31: Marcus Ericsson | N31: 9
M32: Max Verstappen | N32: 3003.5
M33: Mick Schumacher | N33: 12
M34: Nicholas Latifi | N34: 9
M35: Nico Hulkenberg | N35: 216
M36: Nikita Mazepin | N36: 0
M37: Nyck De Vries | N37: 2
M38: Oliver Bearman | N38: 63
... M50: Grand Total | N50: 18848.5
